Workbook

Sheet Utama
A1: 1 | B1: Penilaian | H1: Bobot | I1: Nilai | J1: % | L1: Catatan/Keterangan/Penjelasan | M1: Rekomendasi
A2: 2
A3: 3 | B3: A. | C3: PENGUNGKIT | H3: 60 | I3: ='Ctt Eval'!I3 -> 55.57619
A4: 4 | C4: I. | D4: PEMENUHAN | H4: 30 | I4: ='Ctt Eval'!I4 -> 30 | J4: =I4/H4 -> 1
A5: 5 | D5: 1. | E5: MANAJEMEN PERUBAHAN | H5: 4 | I5: ='Ctt Eval'!I5 -> 4 | J5: =I5/H5 -> 1
A6: 22 | D6: 2. | E6: PENATAAN TATALAKSANA | H6: 3.5 | I6: ='Ctt Eval'!I10 -> 3.5 | J6: =I6/H6 -> 1
A7: 35 | D7: 3. | E7: PENATAAN SISTEM MANAJEMEN SDM APARATUR | H7: 5 | I7: ='Ctt Eval'!I14 -> 5 | J7: =I7/H7 -> 1
A8: 60 | D8: 4. | E8: PENGUATAN AKUNTABILITAS | H8: 5 | I8: ='Ctt Eval'!I21 -> 5 | J8: =I8/H8 -> 1
A9: 74 | D9: 5. | E9: PENGUATAN PENGAWASAN | H9: 7.5 | I9: ='Ctt Eval'!I24 -> 7.5 | J9: =I9/H9 -> 1
A10: 102 | D10: 6. | E10: PENINGKATAN KUALITAS PELAYANAN PUBLIK | H10: 5 | I10: ='Ctt Eval'!I30 -> 5 | J10: =I10/H10 -> 1
A11: 118 | C11: II. | D11: REFORM | H11: 30 | I11: ='Ctt Eval'!I34 -> 25.57619 | J11: =I11/H11 -> 0.85253968
A12: 5 | D12: 1. | E12: MANAJEMEN PERUBAHAN | H12: 4 | I12: ='Ctt Eval'!I35 -> 3.1428571 | J12: =I12/H12 -> 0.78571429
A13: 134 | D13: 2. | E13: PENATAAN TATALAKSANA | H13: 3.5 | I13: ='Ctt Eval'!I39 -> 3.5 | J13: =I13/H13 -> 1
A14: 147 | D14: 3. | E14: PENATAAN SISTEM MANAJEMEN SDM APARATUR | H14: 5 | I14: ='Ctt Eval'!I43 -> 5 | J14: =I14/H14 -> 1
A15: 157 | D15: 4. | E15: PENGUATAN AKUNTABILITAS | H15: 5 | I15: ='Ctt Eval'!I47 -> 4.2 | J15: =I15/H15 -> 0.84
A16: 182 | D16: 5. | E16: PENGUATAN PENGAWASAN | H16: 7.5 | I16: ='Ctt Eval'!I51 -> 4.7333333 | J16: =I16/H16 -> 0.63111111
A17: 203 | D17: 6. | E17: PENINGKATAN KUALITAS PELAYANAN PUBLIK | H17: 5 | I17: ='Ctt Eval'!I55 -> 5 | J17: =I17/H17 -> 1
A18: 211 | B18: TOTAL PENGUNGKIT | I18: ='Ctt Eval'!I58 -> 55.57619 | J18: =I18/H3 -> 0.92626984
A19: 212
A20: 214 | B20: B. | C20: HASIL | H20: 40 | I20: ='Ctt Eval'!I60 -> 40
A21: 215 | C21: I. | D21: BIROKRASI YANG BERSIH DAN AKUNTABEL | H21: 22.5 | I21: ='Ctt Eval'!I61 -> 22.5 | J21: =I21/H21 -> 1
A22: 216 | D22: a | E22: Nilai Survey Persepsi Korupsi (Survei Eksternal : Indeks Persepsi Anti Korupsi/ IPAK) | H22: 17.5 | I22: ='Ctt Eval'!I62 -> 17.5 | J22: =I22/H22 -> 1
A23: 218 | D23: b | E23: Capaian Kinerja Lebih Baik dari pada Capaian Kinerja Sebelumnya | H23: 5 | I23: ='Ctt Eval'!I63 -> 5 | J23: =I23/H23 -> 1
A24: 219 | C24: II. | D24: PELAYANAN PUBLIK YANG PRIMA | H24: 17.5 | I24: ='Ctt Eval'!I64 -> 17.5 | J24: =I24/H24 -> 1
A25: 221 | D25: a | E25: Nilai Persepsi Kualitas Pelayanan (Survei Eksternal : Indeks Persepsi Kualitas Pelayanan Publik / IPKP) | H25: 17.5 | I25: ='Ctt Eval'!I65 -> 17.5 | J25: =I25/H25 -> 1
A26: 222 | B26: TOTAL HASIL | I26: =I20 -> 40 | J26: =I26/H20 -> 1
A27: 223
B28: NILAI EVALUASI REFORMASI BIROKRASI | I28: ='Ctt Eval'!I68 -> 95.57619

Sheet Ctt Eval
A1: 1 | B1: Penilaian | H1: Bobot | I1: Nilai | J1: % | L1: Catatan/Keterangan/Penjelasan
A2: 2
A3: 3 | B3: A. | C3: PENGUNGKIT | H3: 60 | I3: =I58 -> 55.57619
A4: 4 | C4: I. | D4: PEMENUHAN | H4: 30 | I4: ='LKE ZI'!L5 -> 30 | J4: =I4/H4 -> 1
A5: 5 | D5: 1. | E5: MANAJEMEN PERUBAHAN | H5: 4 | I5: ='LKE ZI'!L6 -> 4 | J5: =I5/H5 -> 1
A6: 6 | E6: i. | F6: Tim Reformasi Birokrasi | H6: 0.5 | I6: ='LKE ZI'!L7 -> 0.5 | J6: =I6/H6 -> 1
A7: 9 | E7: ii. | F7: Rencana Pembangunan Zona Integritas | H7: 1 | I7: ='LKE ZI'!L10 -> 1 | J7: =I7/H7 -> 1
A8: 13 | E8: iii. | F8: Pemantauan dan Evaluasi Pembangunan WBK/WBBM | H8: 1 | I8: ='LKE ZI'!L14 -> 1 | J8: =I8/H8 -> 1
A9: 17 | E9: iv. | F9: Perubahan Pola Pikir dan Budaya Kerja | H9: 1.5 | I9: ='LKE ZI'!L18 -> 1.5 | J9: =I9/H9 -> 1
A10: 22 | D10: 2. | E10: PENATAAN TATALAKSANA | H10: 3.5 | I10: ='LKE ZI'!L23 -> 3.5 | J10: =I10/H10 -> 1
A11: 23 | E11: i. | F11: Prosedur Operasional Tetap (SOP) Kegiatan Utama | H11: 1 | I11: ='LKE ZI'!L24 -> 1 | J11: =I11/H11 -> 1
A12: 27 | E12: ii. | F12: Sistem Pemerintahan Berbasis Elektronik (SPBE) | H12: 2 | I12: ='LKE ZI'!L28 -> 2 | J12: =I12/H12 -> 1
A13: 32 | E13: iii. | F13: Keterbukaan Informasi Publik | H13: 0.5 | I13: ='LKE ZI'!L33 -> 0.5 | J13: =I13/H13 -> 1
A14: 35 | D14: 3. | E14: PENATAAN SISTEM MANAJEMEN SDM APARATUR | H14: 5 | I14: ='LKE ZI'!L36 -> 5 | J14: =I14/H14 -> 1
A15: 36 | E15: i. | F15: Perencanaan Kebutuhan Pegawai sesuai dengan Kebutuhan Organisasi | H15: 0.25 | I15: ='LKE ZI'!L37 -> 0.25 | J15: =I15/H15 -> 1
A16: 40 | E16: ii. | F16: Pola Mutasi Internal | H16: 0.5 | I16: ='LKE ZI'!L41 -> 0.5 | J16: =I16/H16 -> 1
A17: 44 | E17: iii. | F17: Pengembangan Pegawai Berbasis Kompetensi | H17: 1.25 | I17: ='LKE ZI'!L45 -> 1.25 | J17: =I17/H17 -> 1
A18: 51 | E18: iv. | F18: Penetapan Kinerja Individu | H18: 2 | I18: ='LKE ZI'!L52 -> 2 | J18: =I18/H18 -> 1
A19: 56 | E19: v. | F19: Penegakan Aturan Disiplin/Kode Etik/Kode Perilaku Pegawai | H19: 0.75 | I19: ='LKE ZI'!L57 -> 0.75 | J19: =I19/H19 -> 1
A20: 58 | E20: vi. | F20: Sistem Informasi Kepegawaian | H20: 0.25 | I20: ='LKE ZI'!L59 -> 0.25 | J20: =I20/H20 -> 1
A21: 60 | D21: 4. | E21: PENGUATAN AKUNTABILITAS | H21: 5 | I21: ='LKE ZI'!L61 -> 5 | J21: =I21/H21 -> 1
A22: 61 | E22: i. | F22: Keterlibatan Pimpinan | H22: 2.5 | I22: ='LKE ZI'!L62 -> 2.5 | J22: =I22/H22 -> 1
A23: 65 | E23: ii. | F23: Pengelolaan Akuntabilitas Kinerja | H23: 2.5 | I23: ='LKE ZI'!L66 -> 2.5 | J23: =I23/H23 -> 1
A24: 74 | D24: 5. | E24: PENGUATAN PENGAWASAN | H24: 7.5 | I24: ='LKE ZI'!L75 -> 7.5 | J24: =I24/H24 -> 1
A25: 75 | E25: i. | F25: Pengendalian Gratifikasi | H25: 1.5 | I25: ='LKE ZI'!L76 -> 1.5 | J25: =I25/H25 -> 1
A26: 78 | E26: ii. | F26: Penerapan Sistem Pengendalian Intern Pemerintah (SPIP) | H26: 1.5 | I26: ='LKE ZI'!L79 -> 1.5 | J26: =I26/H26 -> 1
A27: 83 | E27: iii. | F27: Pengaduan Masyarakat | H27: 1.5 | I27: ='LKE ZI'!L84 -> 1.5 | J27: =I27/H27 -> 1
A28: 91 | E28: iv. | F28: Whistle-Blowing System | H28: 1.5 | I28: ='LKE ZI'!L89 -> 1.5 | J28: =I28/H28 -> 1
A29: 96 | E29: v. | F29: Penanganan Benturan Kepentingan | H29: 1.5 | I29: ='LKE ZI'!L94 -> 1.5 | J29: =I29/H29 -> 1
A30: 102 | D30: 6. | E30: PENINGKATAN KUALITAS PELAYANAN PUBLIK | H30: 5 | I30: ='LKE ZI'!L100 -> 5 | J30: =I30/H30 -> 1
A31: 103 | E31: i. | F31: Standar Pelayanan | H31: 1.5 | I31: ='LKE ZI'!L101 -> 1 | J31: =I31/H31 -> 0.66666667
A32: 108 | E32: ii. | F32: Budaya Pelayanan Prima | H32: 2 | I32: ='LKE ZI'!L106 -> 1 | J32: =I32/H32 -> 0.5
A33: 114 | E33: iii. | F33: Penilaian Kepuasan Terhadap Pelayanan | H33: 1.5 | I33: ='LKE ZI'!L117 -> 1 | J33: =I33/H33 -> 0.66666667
A34: 118 | C34: II. | D34: REFORM | H34: 30 | I34: ='LKE ZI'!L125 -> 25.57619 | J34: =I34/H34 -> 0.85253968
A35: 5 | D35: 1. | E35: MANAJEMEN PERUBAHAN | H35: 4 | I35: ='LKE ZI'!L126 -> 3.1428571 | J35: =I35/H35 -> 0.78571429
A36: 120 | E36: i. | F36: Komitmen dalam Perubahan | H36: 2 | I36: ='LKE ZI'!L127 -> 1.1428571 | J36: =I36/H36 -> 0.57142857
A37: 128 | E37: ii. | F37: Komitmen Pimpinan | G37: Komitmen Pimpinan | H37: 1 | I37: ='LKE ZI'!L134 -> 1 | J37: =I37/H37 -> 1
A38: 130 | E38: iii. | F38: Membangun Budaya Kerja | G38: Membangun Budaya Kerja | H38: 1 | I38: ='LKE ZI'!L136 -> 1 | J38: =I38/H38 -> 1
A39: 134 | D39: 2. | E39: PENATAAN TATALAKSANA | H39: 3.5 | I39: ='LKE ZI'!L138 -> 3.5 | J39: =I39/H39 -> 1
A40: 135 | E40: i. | F40: Peta Proses Bisnis Mempengaruhi Penyederhanaan Jabatan | H40: 0.5 | I40: ='LKE ZI'!L139 -> 0.5 | J40: =I40/H40 -> 1
...

Sheet LKE ZI
B1: LAMPIRAN III PERATURAN MENTERI PENDAYAGUNAAN APARATUR NEGARA DAN REFORMASI BIROKRASI NOMOR 90 TAHUN 2021 TENTANG PEMBANGUNAN DAN EVALUASI PEMBANGUNAN ZONA INTEGRITAS MENUJU WILAYAH BEBAS DARI KORUPSI DAN WILAYAH BIROKRASI BERSIH DAN MELAYANI DI INSTANSI PEMERINTAH
A2: 1 | B2: Penilaian | H2: Bobot | I2: Penjelasan | J2: Pilihan Jawaban | K2: Jawaban | L2: Nilai | M2: % | O2: Catatan/Keterangan/Penjelasan
A3: 2
A4: 3 | B4: A. | C4: PENGUNGKIT | H4: 60 | L4: =L198 -> 55.57619 | M4: =L4/H4 -> 0.92626984
A5: 4 | C5: I. | D5: PEMENUHAN | H5: 30 | L5: =SUM(L6,L23,L36,L61,L75,L100) -> 30 | M5: =L5/H5 -> 1
A6: 5 | D6: 1. | E6: MANAJEMEN PERUBAHAN | H6: 4 | L6: =SUM(L7,L10,L14,L18) -> 4 | M6: =L6/H6 -> 1
A7: 6 | E7: i. | F7: Penyusunan Tim Kerja | H7: 0.5 | L7: =AVERAGE(L8:L9)*H7 -> 0.5 | M7: =L7/H7 -> 1
A8: 7 | F8: a. | G8: Unit kerja telah membentuk tim untuk melakukan pembangunan Zona Integritas | I8: Ya, jika Tim telah dibentuk di dalam unit kerja. | J8: Ya | K8: Ya | L8: =IF(J8="Ya/Tidak",IF(K8="Ya",1,IF(K8="Tidak",0,"Blm Diisi")),IF(J8="A/B/C",IF(K8="A",1,IF(K8="B",0.5,IF(K8="C",0,"Blm Diisi"))),IF(J8="A/B/C/D",IF(K8="A",1,IF(K8="B",0.67,IF(K8="C",0.33,IF(K8="D",0,"Blm Diisi")))),IF(J8="A/B/C/D/E",IF(K8="A",1,IF(K8="B",0.75,IF(K8="C",0.5,IF(K8="D",0.25,IF(K8="E",0,"Blm Diisi"))))),IF(J8="%",IF(K8="","Blm Diisi",K8),IF(J8="Jumlah",IF(K8="","Blm Diisi",""),IF(J8="Rupiah",IF(K8="","Blm Diisi",""),IF(J8="","","-")))))))) -> - | O8: Terdapat Pembentukan Penunjukan Unit Kerja yang akan mengimplementasikan ZI melalui SK Kepala DInas Terdapat Pembentukan Tim Kerja yang akan mengimplementasikan ZI melalui SK Kepala Puskesmas | P8: SK Kepala OPD Ttg Tim Kerja Pembangunan (1 Tahun) Tim Satgas (melibatkan semua): Penanggung Jawab Ketua Anggota | Q8: https://drive.google.com/file/d/1Zu-e_vh46AKarvxKlJ3RqrRToPQ-O5wn/view?usp=sharing
A9: 8 | F9: b. | G9: Penentuan anggota Tim dipilih melalui prosedur/mekanisme yang jelas | I9: a. Jika dengan prosedur/mekanisme yang jelas dan mewakili seluruh unsur dalam unit kerja b. Jika sebagian menggunakan prosedur yang mewakili sebagian besar unsur dalam unit kerja c. Jika tidak di seleksi. | J9: A/B/C | K9: A | L9: =IF(J9="Ya/Tidak",IF(K9="Ya",1,IF(K9="Tidak",0,"Blm Diisi")),IF(J9="A/B/C",IF(K9="A",1,IF(K9="B",0.5,IF(K9="C",0,"Blm Diisi"))),IF(J9="A/B/C/D",IF(K9="A",1,IF(K9="B",0.67,IF(K9="C",0.33,IF(K9="D",0,"Blm Diisi")))),IF(J9="A/B/C/D/E",IF(K9="A",1,IF(K9="B",0.75,IF(K9="C",0.5,IF(K9="D",0.25,IF(K9="E",0,"Blm Diisi"))))),IF(J9="%",IF(K9="","Blm Diisi",K9),IF(J9="Jumlah",IF(K9="","Blm Diisi",""),IF(J9="Rupiah",IF(K9="","Blm Diisi",""),IF(J9="","","-")))))))) -> 1 | O9: Pembentukan Tim Kerja di pilih melaui mekanisme dan prosedur yang jelas melalui penetapan SK pembentukan Tim Kerja ZI | P9: SK Kepala OPD Ttg SOP Prosedur/Mekanisme Penentuan Tim. Memuat kriteria tim: 1) Berstatus sebagai PNS OPD Kota Tangerang Selatan. 2) Bersedia melakukan perubahan. 3) Bersedia bekerja dalam tim. 4) Bertanggung jawab atas tugas yang diberikan. 5) Memiliki kompetensi dan pengalaman pada jabatan yang diusulkan. Bukti Penentuan Tim: 1. Mekanisme Rapat (apabila). a. Undangan Rapat b. Notulensi: Memuat hasil mufakat ketua tim dan penanggungjawab yang diusulakn peserta rapat sesuai kriteria). Memuat usulan penanggung jawab pokja terkait anggota tim dengan kriteria yang sama dan ditetapan mufakat oleh seluruh peserta rapat. c. Absensi Rapat d. Dokumentasi Rapat 2. Seleksi (apabila). a. SK Tim Panitia Seleksi. b. Kertas Kerja Pemilihan Tim Kerja c. Dokumentasi seleksi. d. Laporan Pelaksanaan Seleksi Riwayat Hidup dan Rekam Jejak Tim Kerja | Q9: https://drive.google.com/file/d/1rfKgFcJHrRQXH--LbX9d76e1n64DqpMv/view?usp=sharing
A10: 9 | E10: ii. | F10: Rencana Pembangunan Zona Integritas | H10: 1 | L10: =AVERAGE(L11:L13)*H10 -> 1 | M10: =L10/H10 -> 1
A11: 10 | F11: a. | G11: Terdapat dokumen rencana kerja pembangunan Zona Integritas menuju WBK/WBBM | I11: Ya, jika memiliki rencana kerja pembangunan Zona Integritas. | J11: Ya/Tidak | K11: Ya | L11: =IF(J11="Ya/Tidak",IF(K11="Ya",1,IF(K11="Tidak",0,"Blm Diisi")),IF(J11="A/B/C",IF(K11="A",1,IF(K11="B",0.5,IF(K11="C",0,"Blm Diisi"))),IF(J11="A/B/C/D",IF(K11="A",1,IF(K11="B",0.67,IF(K11="C",0.33,IF(K11="D",0,"Blm Diisi")))),IF(J11="A/B/C/D/E",IF(K11="A",1,IF(K11="B",0.75,IF(K11="C",0.5,IF(K11="D",0.25,IF(K11="E",0,"Blm Diisi"))))),IF(J11="%",IF(K11="","Blm Diisi",K11),IF(J11="Jumlah",IF(K11="","Blm Diisi",""),IF(J11="Rupiah",IF(K11="","Blm Diisi",""),IF(J11="","","-")))))))) -> 1 | O11: Unit Kerja Telah Memilki Rencana Kerja Pembangunan ZI | P11: 1. Dokumen Renja Pembangunan ZI Tahunan. 2. Dokumen Kegiatan Rapat Penyusunan Rencana Aksi a. Undangan b. Dafar Hadir c. Notulensi dan Dokumentasi d. Laporan Kegiatan e. Dokumen Renaksi 3. Dokumen Kegiatan Rapat Penetapan Rencana Kerja a. Undangan b. Daftar Hadir c. Notulensi dan Dokumentasi d. Laporan Kegiatan e. Dokumen Rencana Kerja Pembangunan ZI menujuk WBK/WBBM yang ditandatangani Kepala PD melalui SK. | Q11: https://drive.google.com/file/d/1XFEXf_miQybAk81F5Q4s1VZFZI8XLXZP/view?usp=sharing
A12: 11 | F12: b. | G12: Dalam dokumen pembangunan terdapat target-target prioritas yang relevan dengan tujuan pembangunan WBK/WBBM | I12: a. Jika semua target-target prioritas relevan dengan tujuanpembangunan WBK/WBBM b. Jika sebagian target-target prioritas relevan dengan tujuan pembangunan WBK/WBBM c. Jika tidak ada target-target prioritas yang relevan dengan tujuan pembangunan WBK/WBBM | J12: A/B/C | K12: A | L12: =IF(J12="Ya/Tidak",IF(K12="Ya",1,IF(K12="Tidak",0,"Blm Diisi")),IF(J12="A/B/C",IF(K12="A",1,IF(K12="B",0.5,IF(K12="C",0,"Blm Diisi"))),IF(J12="A/B/C/D",IF(K12="A",1,IF(K12="B",0.67,IF(K12="C",0.33,IF(K12="D",0,"Blm Diisi")))),IF(J12="A/B/C/D/E",IF(K12="A",1,IF(K12="B",0.75,IF(K12="C",0.5,IF(K12="D",0.25,IF(K12="E",0,"Blm Diisi"))))),IF(J12="%",IF(K12="","Blm Diisi",K12),IF(J12="Jumlah",IF(K12="","Blm Diisi",""),IF(J12="Rupiah",IF(K12="","Blm Diisi",""),IF(J12="","","-")))))))) -> 1 | O12: Terdapat Target Prioritas didalam Penyusunan Rencana Kerja Pembangunan ZI | P12: 2. Dokumen Kegiatan Rapat Penyusunan Target Prioritas Pembangunan ZI (6 area) a. Undangan b. Daftar Hadir c. Notulensi dan Dokumentasi d. Laporan Kegiatan e. Dokumen Renaksi yang memuat Target Prioritas | Q12: https://drive.google.com/file/d/1u0W3JQMH1rbDidqXTcnUh6PmUt6O8I67/view?usp=sharing
A13: 12 | F13: c. | G13: Terdapat mekanisme atau media untuk mensosialisasikan pembangunan WBK/WBBM | I13: a. Jika telah dilakukan pengelolaan media/aktivitas interaktif yang efektif untuk menginformasikan pembangunan ZI kepada internal dan stakeholder secara berkala b. Jika pengelolaan media/aktivitas interaktif dilakukan secara terbatas dan tidak secara berkala c. Jika pengelolaan media/aktivitas interaktif belum dilakukan | J13: A/B/C | K13: A | L13: =IF(J13="Ya/Tidak",IF(K13="Ya",1,IF(K13="Tidak",0,"Blm Diisi")),IF(J13="A/B/C",IF(K13="A",1,IF(K13="B",0.5,IF(K13="C",0,"Blm Diisi"))),IF(J13="A/B/C/D",IF(K13="A",1,IF(K13="B",0.67,IF(K13="C",0.33,IF(K13="D",0,"Blm Diisi")))),IF(J13="A/B/C/D/E",IF(K13="A",1,IF(K13="B",0.75,IF(K13="C",0.5,IF(K13="D",0.25,IF(K13="E",0,"Blm Diisi"))))),IF(J13="%",IF(K13="","Blm Diisi",K13),IF(J13="Jumlah",IF(K13="","Blm Diisi",""),IF(J13="Rupiah",IF(K13="","Blm Diisi",""),IF(J13="","","-")))))))) -> 1 | O13: Terdapat Media Informasi Pembangunan ZI yang Interaktif sebagai Media Informasi Kepada Pihak Lain | P13: 1. SOP Mekanisme Sosialisasi Pembangunan ZI 2. Bukti Sosialisasi Pembangunan ZI a. Bentuk Kegiatan Sosialisasi 1) Sosialisasi Internal Berkala - Undangan - Daftar Hadir - Notulensi dan dokumentasi - Laporan Kegiatan - Bulanan / Triwulanan / Semesteran 2) Sosialisasi Stakeholder Berkala - Undangan - Daftar Hadir - Notulensi dan dokumentasi - Laporan Kegiatan - Bulanan / Triwulanan / Semesteran 3) Banner, Spanduk, dll sejenis Sosiliasi melalui virtual : Undangan, absensi onlline (google form), link room zoom, screen shoot zoom peserta. b. Media Sosial Screen shoot | Q13: https://drive.google.com/file/d/1rarGzXFQdppWzuOedfSRRQtixI5gmCP5/view?usp=sharing
A14: 13 | E14: iii. | F14: Pemantauan dan Evaluasi Pembangunan WBK/WBBM | H14: 1 | L14: =AVERAGE(L15:L17)*H14 -> 1 | M14: =L14/H14 -> 1
A15: 14 | F15: a. | G15: Seluruh kegiatan pembangunan sudah dilaksanakan sesuai dengan rencana | I15: a. Jika semua kegiatan pembangunan telah dilaksanakan sesuai dengan rencana b. Jika sebagian besar kegiatan pembangunan telah dilaksanakan sesuai dengan rencana c. Jika sebagian kecil kegiatan pembangunan telah dilaksanakan sesuai dengan rencana d. Jika belum ada kegiatan pembangunan yang dilakukan sesuai dengan rencana | J15: A/B/C/D | K15: A | L15: =IF(J15="Ya/Tidak",IF(K15="Ya",1,IF(K15="Tidak",0,"Blm Diisi")),IF(J15="A/B/C",IF(K15="A",1,IF(K15="B",0.5,IF(K15="C",0,"Blm Diisi"))),IF(J15="A/B/C/D",IF(K15="A",1,IF(K15="B",0.67,IF(K15="C",0.33,IF(K15="D",0,"Blm Diisi")))),IF(J15="A/B/C/D/E",IF(K15="A",1,IF(K15="B",0.75,IF(K15="C",0.5,IF(K15="D",0.25,IF(K15="E",0,"Blm Diisi"))))),IF(J15="%",IF(K15="","Blm Diisi",K15),IF(J15="Jumlah",IF(K15="","Blm Diisi",""),IF(J15="Rupiah",IF(K15="","Blm Diisi",""),IF(J15="","","-")))))))) -> 1 | O15: Pembangunan ZI telah dilakukan sesuai dengan rencana seperti terdapat dalam form Rencana Aksi | P15: Laporan Monev Berkala Pelaksanaan Pembangunan ZI oleh Tim Internal (Bulanan/Triwulanan/Semesteran) Jika realisasi 100% : a Jika realisasi >75% s.d. <100% : b Jika realisasi <=75% : c | Q15: https://drive.google.com/file/d/1ChQj4wEmXBx0MOc-64CGaWnGMKlS8fUi/view?usp=sharing
A16: 15 | F16: b. | G16: Terdapat monitoring dan evaluasi terhadap pembangunan Zona Integritas | I16: a. Jika monitoring dan evaluasi melibatkan pimpinan dan dilakukan secara berkala b. Jika monitoring dan evaluasi melibatkan pimpinan tetapi tidak secara berkala c. Jika monitoring dan evaluasi tidak melibatkan pimpinan dan tidak secara berkala d. Jika tidak terdapat monitoring dan evaluasi terhadap pembangunan zona integritas | J16: A/B/C/D | K16: A | L16: =IF(J16="Ya/Tidak",IF(K16="Ya",1,IF(K16="Tidak",0,"Blm Diisi")),IF(J16="A/B/C",IF(K16="A",1,IF(K16="B",0.5,IF(K16="C",0,"Blm Diisi"))),IF(J16="A/B/C/D",IF(K16="A",1,IF(K16="B",0.67,IF(K16="C",0.33,IF(K16="D",0,"Blm Diisi")))),IF(J16="A/B/C/D/E",IF(K16="A",1,IF(K16="B",0.75,IF(K16="C",0.5,IF(K16="D",0.25,IF(K16="E",0,"Blm Diisi"))))),IF(J16="%",IF(K16="","Blm Diisi",K16),IF(J16="Jumlah",IF(K16="","Blm Diisi",""),IF(J16="Rupiah",IF(K16="","Blm Diisi",""),IF(J16="","","-")))))))) -> 1 | O16: Evaluasi dan Monitoring ZI dilakukan secara berkala dan melibatkan Pimpinan | P16: Dokumen Kegiatan Monev Pembangunan ZI: a. Undangan b. Daftar Hadir (Melibatkan Pimpinan) c. Notulensi dan Dokumentasi (Melibatkan Pimpinan) d. Laporan Monev Berkala (Bulanan/Triwulanan/Semesteran) | Q16: https://drive.google.com/file/d/1lyTuht7JfN448Dm-tTLuxruZ3TgDPTW_/view?usp=sharing
A17: 16 | F17: c. | G17: Hasil Monitoring dan Evaluasi telah ditindaklanjuti | I17: a. Jika semua catatan/rekomendasi hasil monitoring dan evaluasi tim internal atas persiapan dan pelaksanaan kegiatan Unit WBK/WBBM telah ditindaklanjuti b. Jika sebagian besar catatan/rekomendasi hasil monitoring danevaluasi tim internal atas persiapan dan pelaksanaan kegiatanUnit WBK/WBBM telah ditindaklanjuti c. Jika sebagian kecil catatan/rekomendasi hasil monitoring dan evaluasi tim internal atas persiapan dan pelaksanaan kegiatan Unit WBK/WBBM telah ditindaklanjuti d. Jika catatan/rekomendasi hasil monitoring dan evaluasi tim internal atas persiapan dan pelaksanaan kegiatan Unit WBK/WBBM belum ditindaklanjuti | J17: A/B/C/D | K17: A | L17: =IF(J17="Ya/Tidak",IF(K17="Ya",1,IF(K17="Tidak",0,"Blm Diisi")),IF(J17="A/B/C",IF(K17="A",1,IF(K17="B",0.5,IF(K17="C",0,"Blm Diisi"))),IF(J17="A/B/C/D",IF(K17="A",1,IF(K17="B",0.67,IF(K17="C",0.33,IF(K17="D",0,"Blm Diisi")))),IF(J17="A/B/C/D/E",IF(K17="A",1,IF(K17="B",0.75,IF(K17="C",0.5,IF(K17="D",0.25,IF(K17="E",0,"Blm Diisi"))))),IF(J17="%",IF(K17="","Blm Diisi",K17),IF(J17="Jumlah",IF(K17="","Blm Diisi",""),IF(J17="Rupiah",IF(K17="","Blm Diisi",""),IF(J17="","","-")))))))) -> 1 | O17: Dilakukan Tindak Lanjut terhadap Hasil Monitoring dan Evaluasi | P17: Dokumen Kegiatan Tindak Lanjut atas Persiapan & Hasil Monev Pembangunan ZI oleh Tim Internal: a. Undangan b. Daftar Hadir c. Notulensi dan Dokumentasi d. Laporan Monev Berkala (Bulanan/Triwulanan/Semesteran) Rapat Pembahasan Tindak Lanjut dilaksanakan bersamaan dengan rapat pembahasan Monev dan rapat Persiapan. Jika Tindak Lanjut 100% : a Jika realisasi >75% s.d. <100% : b Jika realisasi >50% <=75% : c Jika tindak lanjut NIHIL : d | Q17: https://drive.google.com/file/d/1_XgHk3SYmn589KU05ziQao-A8AS0Mbh4/view?usp=sharing
A18: 17 | E18: iv. | F18: Perubahan pola pikir dan budaya kerja | H18: 1.5 | L18: =AVERAGE(L19:L22)*H18 -> 1.5 | M18: =L18/H18 -> 1
A19: 18 | F19: a. | G19: Pimpinan berperan sebagai role model dalam pelaksanaan Pembangunan WBK/WBBM | I19: ya, jika pimpinan menjadi contoh pelaksanaan nilai-nilai organisasi. | J19: Ya/Tidak | K19: Ya | L19: =IF(J19="Ya/Tidak",IF(K19="Ya",1,IF(K19="Tidak",0,"Blm Diisi")),IF(J19="A/B/C",IF(K19="A",1,IF(K19="B",0.5,IF(K19="C",0,"Blm Diisi"))),IF(J19="A/B/C/D",IF(K19="A",1,IF(K19="B",0.67,IF(K19="C",0.33,IF(K19="D",0,"Blm Diisi")))),IF(J19="A/B/C/D/E",IF(K19="A",1,IF(K19="B",0.75,IF(K19="C",0.5,IF(K19="D",0.25,IF(K19="E",0,"Blm Diisi"))))),IF(J19="%",IF(K19="","Blm Diisi",K19),IF(J19="Jumlah",IF(K19="","Blm Diisi",""),IF(J19="Rupiah",IF(K19="","Blm Diisi",""),IF(J19="","","-")))))))) -> 1 | O19: Pimpinan Menjadi contoh (Role Model) dalam setiap kegiatan Puskesmas | P19: xxx xxxx xxxx xxxx | Q19: https://drive.google.com/file/d/1kxGDMd8zJAng01yg3oZEYTNnNILcQlKJ/view?usp=sharing
A20: 19 | F20: b. | G20: Sudah ditetapkan agen perubahan | I20: a. Jika agen perubahan telah ditetapkan dan berkontribusi terhadap perubahan pada unit kerjanya b. Jika agen perubahan telah ditetapkan namun belum berkontribusi terhadap perubahan pada unit kerjanya c. Jika belum terdapat agen perubahan | J20: A/B/C | K20: A | L20: =IF(J20="Ya/Tidak",IF(K20="Ya",1,IF(K20="Tidak",0,"Blm Diisi")),IF(J20="A/B/C",IF(K20="A",1,IF(K20="B",0.5,IF(K20="C",0,"Blm Diisi"))),IF(J20="A/B/C/D",IF(K20="A",1,IF(K20="B",0.67,IF(K20="C",0.33,IF(K20="D",0,"Blm Diisi")))),IF(J20="A/B/C/D/E",IF(K20="A",1,IF(K20="B",0.75,IF(K20="C",0.5,IF(K20="D",0.25,IF(K20="E",0,"Blm Diisi"))))),IF(J20="%",IF(K20="","Blm Diisi",K20),IF(J20="Jumlah",IF(K20="","Blm Diisi",""),IF(J20="Rupiah",IF(K20="","Blm Diisi",""),IF(J20="","","-")))))))) -> 1 | O20: Telah ditetapkan Agen Perubahan didalam Puskesmas | P20: 1. SK Kepala OPD Ttg Agen Perubahan 2. SOP Mekanisme Pemilihan Agen Perubahan 3. Dokumen Pelaksanaan Kegiatan Penetapan Agen Perubahan: a. Undangan b. Daftar Hadir. c. Notulensi dan dokumentasi. d. Laporan Pelaknsanaan Pemilihan Agen Perubahan e. Riwayat Hidup & Rekam Jejak Agen Perubahan f. Prestasi / Kontribusi Agen Perubahan dalam Pembangunan ZI (dokumen bukti) | Q20: https://drive.google.com/file/d/1YznB2F4uIeyonidOjfGC4UOXrMAN8EKI/view?usp=sharing
A21: 20 | F21: c. | G21: Telah dibangun budaya kerja dan pola pikir di lingkungan organisasi | I21: a. Jika telah dilakukan upaya pembangunan budaya kerja dan pola pikir dan mampu mengurangi resistensi atas perubahan b. Jika telah dilakukan upaya pembangunan budaya kerja dan pola pikir tapi masih terdapat resistensi atas perubahan c. Jika belum terdapat upaya pembangunan budaya kerja dan pola pikir | J21: A/B/C | K21: A | L21: =IF(J21="Ya/Tidak",IF(K21="Ya",1,IF(K21="Tidak",0,"Blm Diisi")),IF(J21="A/B/C",IF(K21="A",1,IF(K21="B",0.5,IF(K21="C",0,"Blm Diisi"))),IF(J21="A/B/C/D",IF(K21="A",1,IF(K21="B",0.67,IF(K21="C",0.33,IF(K21="D",0,"Blm Diisi")))),IF(J21="A/B/C/D/E",IF(K21="A",1,IF(K21="B",0.75,IF(K21="C",0.5,IF(K21="D",0.25,IF(K21="E",0,"Blm Diisi"))))),IF(J21="%",IF(K21="","Blm Diisi",K21),IF(J21="Jumlah",IF(K21="","Blm Diisi",""),IF(J21="Rupiah",IF(K21="","Blm Diisi",""),IF(J21="","","-")))))))) -> 1 | O21: Budaya Kerja dan Pola Pikir Anti Gratifikasi telah diterapkan didalam Puskesmas | P21: 1. Dokumen Pelaksanaan Pembangunan Budaya Kerja & Pola Pikir: a. Dalam bentuk pelatihan, bimbingan teknis, worksop, Pelatihan Kantor Sendiri, Sosialisasi, dll sejenis. - Undangan - Daftar Hadir - Notulensi dan dokumentasi - Laporan Pelaksanaan b. Surat Edaran Ka PD & Media Imbauan 2. Mekanisme Reward & Punishment - SOP - Bukti Penghargaan - Bukti Pemberian Sanksi. 3. Laporan Pemetaatb Tingkat Keterlibatan dan Resistensi Pembangunan ZI. | Q21: https://drive.google.com/file/d/1jYeDPTVe1pAal1uGdxC_HArLnNHVBqkl/view?usp=sharing
A22: 21 | F22: d. | G22: Anggota organisasi terlibat dalam pembangunan Zona Integritas menuju WBK/WBBM | I22: a. Jika semua anggota terlibat dalam pembangunan Zona Integritas menuju WBK/WBBM dan usulan-usulan dari anggota diakomodasikan dalam keputusan b. Jika sebagian besar anggota terlibat dalam pembangunan Zona Integritas menuju WBK/WBBM c. Jika sebagian kecil anggota terlibat dalam pembangunan Zona Integritas menuju WBK/WBBM d. Jika belum ada anggota terlibat dalam pembangunan Zona Integritas menuju WBK/WBBM | J22: A/B/C/D | K22: A | L22: =IF(J22="Ya/Tidak",IF(K22="Ya",1,IF(K22="Tidak",0,"Blm Diisi")),IF(J22="A/B/C",IF(K22="A",1,IF(K22="B",0.5,IF(K22="C",0,"Blm Diisi"))),IF(J22="A/B/C/D",IF(K22="A",1,IF(K22="B",0.67,IF(K22="C",0.33,IF(K22="D",0,"Blm Diisi")))),IF(J22="A/B/C/D/E",IF(K22="A",1,IF(K22="B",0.75,IF(K22="C",0.5,IF(K22="D",0.25,IF(K22="E",0,"Blm Diisi"))))),IF(J22="%",IF(K22="","Blm Diisi",K22),IF(J22="Jumlah",IF(K22="","Blm Diisi",""),IF(J22="Rupiah",IF(K22="","Blm Diisi",""),IF(J22="","","-")))))))) -> 1 | O22: Keterlibatan Seluruh Angota Didalam Pembangunan ZI | P22: 1. Penandatangan Komitmen Pembangunan ZI oleh seluruh pegawai. 2. Penandatanganan Pakta Integritas. 3. Laporan keterlibatan pegawai dalam Pembangunan ZI (salah satunya memuat usulan-usulan tim ZI yang diakomodir dalam Renja ZI. Jika Terlibat 100% : a Jika Terlibat >75% s.d. <100% : b Jika Terlibat >50% <=75% : c Jika Terlibat NIHIL : d | Q22: https://drive.google.com/file/d/1iAh9zIXBI_Xx1OGrj3uxZsGYmEpD2Fbk/view?usp=sharing
A23: 22 | D23: 2. | E23: PENATAAN TATALAKSANA | H23: 3.5 | L23: =SUM(L24,L28,L33) -> 3.5 | M23: =L23/H23 -> 1
A24: 23 | E24: i. | F24: Prosedur Operasional Tetap (SOP) Kegiatan Utama | H24: 1 | L24: =AVERAGE(L25:L27)*H24 -> 1 | M24: =L24/H24 -> 1
A25: 24 | F25: a. | G25: SOP mengacu pada peta proses bisnis instansi | I25: a. Jika semua SOP unit telah mengacu peta proses bisnis dan juga melakukan inovasi yang selaras b. Jika semua SOP unit telah mengacu peta proses bisnis c. Jika sebagian SOP unit telah mengacu peta proses bisnis d. Jika belum terdapat SOP unit yang mengacu peta proses bisnis | J25: A/B/C/D | K25: A | L25: =IF(J25="Ya/Tidak",IF(K25="Ya",1,IF(K25="Tidak",0,"Blm Diisi")),IF(J25="A/B/C",IF(K25="A",1,IF(K25="B",0.5,IF(K25="C",0,"Blm Diisi"))),IF(J25="A/B/C/D",IF(K25="A",1,IF(K25="B",0.67,IF(K25="C",0.33,IF(K25="D",0,"Blm Diisi")))),IF(J25="A/B/C/D/E",IF(K25="A",1,IF(K25="B",0.75,IF(K25="C",0.5,IF(K25="D",0.25,IF(K25="E",0,"Blm Diisi"))))),IF(J25="%",IF(K25="","Blm Diisi",K25),IF(J25="Jumlah",IF(K25="","Blm Diisi",""),IF(J25="Rupiah",IF(K25="","Blm Diisi",""),IF(J25="","","-")))))))) -> 1 | O25: Penetapan Agen Perubahan ditetapkan berdasarkan penempatan tiap-tiap profesi Seluruh SOP telah mengacu kepada Peta Proses Bisnis (PROBIS) | P25: 1. Proses Bisnis PD 2. Rekapitulasi SOP AP 3. Laporan Inovasi Layanan (SOP) | Q25: https://drive.google.com/file/d/1limA4IEf3WiiwGO8RW03iC-kmDExpEwK/view?usp=sharing
A26: 25 | F26: b. | G26: Prosedur operasional tetap (SOP) telah diterapkan | I26: a. Jika unit telah menerapkan seluruh SOP yang ditetapkan organisasi dan juga melakukan inovasi pada SOP yang diterapkan b. Jika unit telah menerapkan seluruh SOP yang ditetapkan organisasi c. Jika unit telah menerapkan sebagian besar SOP yang ditetapkan organisasi d. Jika unit telah menerapkan sebagian kecil SOP yang ditetapkan organisasi e. Jika unit belum menerapkan SOP yang telah ditetapkan organisasi | J26: A/B/C/D/E | K26: A | L26: =IF(J26="Ya/Tidak",IF(K26="Ya",1,IF(K26="Tidak",0,"Blm Diisi")),IF(J26="A/B/C",IF(K26="A",1,IF(K26="B",0.5,IF(K26="C",0,"Blm Diisi"))),IF(J26="A/B/C/D",IF(K26="A",1,IF(K26="B",0.67,IF(K26="C",0.33,IF(K26="D",0,"Blm Diisi")))),IF(J26="A/B/C/D/E",IF(K26="A",1,IF(K26="B",0.75,IF(K26="C",0.5,IF(K26="D",0.25,IF(K26="E",0,"Blm Diisi"))))),IF(J26="%",IF(K26="","Blm Diisi",K26),IF(J26="Jumlah",IF(K26="","Blm Diisi",""),IF(J26="Rupiah",IF(K26="","Blm Diisi",""),IF(J26="","","-")))))))) -> 1 | O26: SOP telah ditetapkan | P26: Laporan Monitoring Penerapan SOP & Inovasi Layanan | Q26: https://drive.google.com/file/d/1KFIWvj_Q98G_OCTQTQS8-e3R_U4HAJtH/view?usp=sharing
A27: 26 | F27: c. | G27: Prosedur operasional tetap (SOP) telah dievaluasi | I27: a. Jika seluruh SOP utama telah dievaluasi dan telah ditindaklanjuti berupa perbaikan SOP atau usulan perbaikan SOP b. Jika sebagian besar SOP utama telah dievaluasi dan telah ditindaklanjuti berupa perbaikan SOP atau usulan perbaikan SOP c. Jika sebagian besar SOP utama telah dievaluasi tetapi belum ditindaklanjuti d. Jika sebagian kecil SOP utama telah dievaluasi e. Jika SOP belum pernah dievaluasi | J27: A/B/C/D/E | K27: A | L27: =IF(J27="Ya/Tidak",IF(K27="Ya",1,IF(K27="Tidak",0,"Blm Diisi")),IF(J27="A/B/C",IF(K27="A",1,IF(K27="B",0.5,IF(K27="C",0,"Blm Diisi"))),IF(J27="A/B/C/D",IF(K27="A",1,IF(K27="B",0.67,IF(K27="C",0.33,IF(K27="D",0,"Blm Diisi")))),IF(J27="A/B/C/D/E",IF(K27="A",1,IF(K27="B",0.75,IF(K27="C",0.5,IF(K27="D",0.25,IF(K27="E",0,"Blm Diisi"))))),IF(J27="%",IF(K27="","Blm Diisi",K27),IF(J27="Jumlah",IF(K27="","Blm Diisi",""),IF(J27="Rupiah",IF(K27="","Blm Diisi",""),IF(J27="","","-")))))))) -> 1 | O27: SOP Utama telah dievaluasi dan telah ditindaklanjutu secara berkala termasuk pada saat proses Audit Internal | P27: Laporan Evaluasi Penerapan SOP & Inovasi Layanan Laporan Tindak Lanjut Perbaikan SOP atau Usulan Perbaikan SOP | Q27: https://drive.google.com/file/d/1o1sioaKwA_WddWma1Lyl9DVnHX9kCcWF/view?usp=sharing
A28: 27 | E28: ii. | F28: Sistem Pemerintahan Berbasis Elektronik (SPBE) | H28: 2 | L28: =AVERAGE(L29:L32)*H28 -> 2 | M28: =L28/H28 -> 1
A29: 28 | F29: a. | G29: Sistem pengukuran kinerja unit sudah menggunakan teknologi informasi | I29: a. Jika unit memiliki sistem pengukuran kinerja (e-performance/e-sakip) yang menggunakan teknologi informasi dan juga melakukan inovasi b. Jika unit memiliki sistem pengukuran kinerja (e-performance/e-sakip) yang menggunakan teknologi informasi c. Jika belum memiliki sistem pengukuran kinerja (e-performance/e-sakip) yang menggunakan teknologi informasi | J29: A/B/C | K29: A | L29: =IF(J29="Ya/Tidak",IF(K29="Ya",1,IF(K29="Tidak",0,"Blm Diisi")),IF(J29="A/B/C",IF(K29="A",1,IF(K29="B",0.5,IF(K29="C",0,"Blm Diisi"))),IF(J29="A/B/C/D",IF(K29="A",1,IF(K29="B",0.67,IF(K29="C",0.33,IF(K29="D",0,"Blm Diisi")))),IF(J29="A/B/C/D/E",IF(K29="A",1,IF(K29="B",0.75,IF(K29="C",0.5,IF(K29="D",0.25,IF(K29="E",0,"Blm Diisi"))))),IF(J29="%",IF(K29="","Blm Diisi",K29),IF(J29="Jumlah",IF(K29="","Blm Diisi",""),IF(J29="Rupiah",IF(K29="","Blm Diisi",""),IF(J29="","","-")))))))) -> 1 | O29: Unit telah memiliki sistem pengukuran kinerja menggunakan teknologi informasi e-sakip | P29: 1. Capture e-performance / e- sakip. 2. Inovasi Internal PD terkait Pengukuran Kinerja | Q29: https://drive.google.com/file/d/1UmJ3f5Y6G02YEe300UWoR9z3UkNckT3B/view?usp=sharing
A30: 29 | F30: b. | G30: Operasionalisasi manajemen SDM sudah menggunakan teknologi informasi | I30: a. Jika unit memiliki operasionalisasi manajemen SDM yang menggunakan teknologi informasi dan juga melakukan inovasi b. Jika unit memiliki operasionalisasi manajemen SDM yang menggunakan teknologi informasi secara terpusat c. Jika belum menggunakan teknologi informasi dalam operasionalisasi manajemen SDM | J30: A/B/C | K30: A | L30: =IF(J30="Ya/Tidak",IF(K30="Ya",1,IF(K30="Tidak",0,"Blm Diisi")),IF(J30="A/B/C",IF(K30="A",1,IF(K30="B",0.5,IF(K30="C",0,"Blm Diisi"))),IF(J30="A/B/C/D",IF(K30="A",1,IF(K30="B",0.67,IF(K30="C",0.33,IF(K30="D",0,"Blm Diisi")))),IF(J30="A/B/C/D/E",IF(K30="A",1,IF(K30="B",0.75,IF(K30="C",0.5,IF(K30="D",0.25,IF(K30="E",0,"Blm Diisi"))))),IF(J30="%",IF(K30="","Blm Diisi",K30),IF(J30="Jumlah",IF(K30="","Blm Diisi",""),IF(J30="Rupiah",IF(K30="","Blm Diisi",""),IF(J30="","","-")))))))) -> 1 | O30: Unit kerja memiliki operasionalisasi manajemen SDM menggunkan teknologi informasi berbasis Aplikasi SIMPEG | P30: 1. Capture IT terkait manajemen SDM. 2. Inovasi Internal PD terkait manajemen SDM | Q30: https://drive.google.com/file/d/1FOzzNYiuTELqa1JvnvqBt3rmWVyUc-lY/view?usp=sharing
A31: 30 | F31: c. | G31: Pemberian pelayanan kepada publik sudah menggunakan teknologi informasi | I31: a. Jika unit memberikan pelayanan kepada publik dengan menggunakan teknologi informasi terpusat/unit sendiri dan terdapat inovasi b. Jika unit memberikan pelayanan kepada publik dengan menggunakan teknologi informasi secara terpusat c. Jika belum memberikan pelayanan kepada publik dengan menggunakan teknologi informasi | J31: A/B/C | K31: A | L31: =IF(J31="Ya/Tidak",IF(K31="Ya",1,IF(K31="Tidak",0,"Blm Diisi")),IF(J31="A/B/C",IF(K31="A",1,IF(K31="B",0.5,IF(K31="C",0,"Blm Diisi"))),IF(J31="A/B/C/D",IF(K31="A",1,IF(K31="B",0.67,IF(K31="C",0.33,IF(K31="D",0,"Blm Diisi")))),IF(J31="A/B/C/D/E",IF(K31="A",1,IF(K31="B",0.75,IF(K31="C",0.5,IF(K31="D",0.25,IF(K31="E",0,"Blm Diisi"))))),IF(J31="%",IF(K31="","Blm Diisi",K31),IF(J31="Jumlah",IF(K31="","Blm Diisi",""),IF(J31="Rupiah",IF(K31="","Blm Diisi",""),IF(J31="","","-")))))))) -> 1 | O31: Unit kerja telah memberikan pelayanan dengan menggunakan Teknologi Informasi | P31: Laporan / Penjelasan IT / Aplikasi / Web Site terkait Pelayanan Publik | Q31: https://drive.google.com/file/d/1Hzqruc6WfaZHwmpUXn6C5zXx4X8TFZ5E/view?usp=sharing
A32: 31 | F32: d | G32: Telah dilakukan monitoring dan dan evaluasi terhadap pemanfaatan teknologi informasi dalam pengukuran kinerja unit, operasionalisasi SDM, dan pemberian layanan kepada publik | I32: a. Jika laporan monitoring dan evaluasi terhadap pemanfaatan teknologi informasi dalam pengukuran kinerja unit, operasionalisasi SDM, dan pemberian layanan kepada publik sudah dilakukan secara berkala b. Jika laporan monitoring dan evaluasi terhadap pemanfaatan teknologi informasi dalam pengukuran kinerja unit, operasionalisasi SDM, dan pemberian layanan kepada publik sudah dilakukan tetapi tidak secara berkala c. Jika tidak terdapat monitoring dan evaluasi terhadap pemanfaatan teknologi informasi dalam pengukuran kinerja unit, operasionalisasi SDM, dan pemberian layanan kepada publik | J32: A/B/C | K32: A | L32: =IF(J32="Ya/Tidak",IF(K32="Ya",1,IF(K32="Tidak",0,"Blm Diisi")),IF(J32="A/B/C",IF(K32="A",1,IF(K32="B",0.5,IF(K32="C",0,"Blm Diisi"))),IF(J32="A/B/C/D",IF(K32="A",1,IF(K32="B",0.67,IF(K32="C",0.33,IF(K32="D",0,"Blm Diisi")))),IF(J32="A/B/C/D/E",IF(K32="A",1,IF(K32="B",0.75,IF(K32="C",0.5,IF(K32="D",0.25,IF(K32="E",0,"Blm Diisi"))))),IF(J32="%",IF(K32="","Blm Diisi",K32),IF(J32="Jumlah",IF(K32="","Blm Diisi",""),IF(J32="Rupiah",IF(K32="","Blm Diisi",""),IF(J32="","","-")))))))) -> 1 | O32: Unit telah melaksanakan Monitoring dan Evaluasi terhadap pemanfaatan Teknologi Informasi yang diterapkan di Puskesmas | P32: Laporan Monitoring Pemanfaatan TI Dalam Pemberian Layanan Publik, meliputi: 1. Pengukuran Kinerja Unit 2. Operasionalisasi SDM 3. Pemberian Layanan Kepada Publik Apabila dalam bentuk rapat: 1. Surat Undangan Monev 2. Daftar Hadir 3. Dokumentasi 4. Notulensi yang memuat monev atas Pemanfaatan TI (Pengukuran Kinerja Unit, Operasionalisasi SDM, Pemberian Layanan Kepada Publik Monev dilakukan secara berkala semesteran / triwulanan / bulanan. | Q32: https://drive.google.com/file/d/1ZRBkGXB7iMvgm4F0mM2W7rsG_d2H1hqa/view?usp=sharing
A33: 32 | E33: iii. | F33: Keterbukaan Informasi Publik | H33: 0.5 | L33: =AVERAGE(L34:L35)*H33 -> 0.5 | M33: =L33/H33 -> 1
A34: 33 | F34: a. | G34: Kebijakan tentang keterbukaan informasi publik telah diterapkan | I34: a. Jika sudah terdapat Pejabat Pengelola Informasi Publik (PPID) yang menyebarkan seluruh informasi yang dapat diakses secara mutakhir dan lengkap b. Jika sudah terdapat PPID yang menyebarkan sebagian informasi yang dapat diakses secara mutakhir dan lengkap c. Jika belum ada PPID dan belum melakukan penyebaran informasi publik | J34: A/B/C | K34: A | L34: =IF(J34="Ya/Tidak",IF(K34="Ya",1,IF(K34="Tidak",0,"Blm Diisi")),IF(J34="A/B/C",IF(K34="A",1,IF(K34="B",0.5,IF(K34="C",0,"Blm Diisi"))),IF(J34="A/B/C/D",IF(K34="A",1,IF(K34="B",0.67,IF(K34="C",0.33,IF(K34="D",0,"Blm Diisi")))),IF(J34="A/B/C/D/E",IF(K34="A",1,IF(K34="B",0.75,IF(K34="C",0.5,IF(K34="D",0.25,IF(K34="E",0,"Blm Diisi"))))),IF(J34="%",IF(K34="","Blm Diisi",K34),IF(J34="Jumlah",IF(K34="","Blm Diisi",""),IF(J34="Rupiah",IF(K34="","Blm Diisi",""),IF(J34="","","-")))))))) -> 1 | O34: Terdapat Pejabat Informasi Publik (PPID) sebagai penyebar informasi yang dapat diakses publik | P34: 1. Perwal/SOP terkait Keterbukaan Informasi Publik 2. SK PPID Kota 3. SK Tim Pengelola Layanan Informasi & Dokumentasi 4. Screen shoot informasi yang disebarkan (web, medsos, dll) | Q34: https://drive.google.com/file/d/1VFyDF1vDqMfnQh2hgNnPDVA97nghuNAE/view?usp=sharing
A35: 34 | F35: b. | G35: Telah dilakukan monitoring dan evaluasi pelaksanaan kebijakan keterbukaan informasi publik | I35: a. Jika dilakukan monitoring dan evaluasi pelaksanaan kebijakan keterbukaan informasi publik dan telah ditindaklanjuti b. Jika monitoring dan evaluasi pelaksanaan kebijakan keterbukaan informasi publik telah dilakukan tetapi belum ditindaklanjuti c. Jika monitoring dan evaluasi pelaksanaan kebijakan keterbukaan informasi publik belum dilakukan | J35: A/B/C | K35: A | L35: =IF(J35="Ya/Tidak",IF(K35="Ya",1,IF(K35="Tidak",0,"Blm Diisi")),IF(J35="A/B/C",IF(K35="A",1,IF(K35="B",0.5,IF(K35="C",0,"Blm Diisi"))),IF(J35="A/B/C/D",IF(K35="A",1,IF(K35="B",0.67,IF(K35="C",0.33,IF(K35="D",0,"Blm Diisi")))),IF(J35="A/B/C/D/E",IF(K35="A",1,IF(K35="B",0.75,IF(K35="C",0.5,IF(K35="D",0.25,IF(K35="E",0,"Blm Diisi"))))),IF(J35="%",IF(K35="","Blm Diisi",K35),IF(J35="Jumlah",IF(K35="","Blm Diisi",""),IF(J35="Rupiah",IF(K35="","Blm Diisi",""),IF(J35="","","-")))))))) -> 1 | O35: Unit telah melakukan Monitoring dan Evaluasi terhadap pelaksanaan Kebijakan Keterbukaan Informasi Publik | P35: 1. Pelaksanaan Monev atas Kebijakan Keterbukaan Informasi Publik: a. Laporan Monev Bulanan/Triwulanan b. Surat Undangan Kegiatan Monev. c. Daftar Hadir. d. Dokumentasi. e. Notulensi 2. Tindak Lanjut atas Rekomendasi Monev | Q35: https://drive.google.com/file/d/1Mf8A0Je2TNlKqf4yWbHmvGIGo4joxGwG/view?usp=sharing
A36: 35 | D36: 3. | E36: PENATAAN SISTEM MANAJEMEN SDM APARATUR | H36: 5 | L36: =SUM(L37,L41,L45,L52,L57,L59) -> 5 | M36: =L36/H36 -> 1
A37: 36 | E37: i. | F37: Perencanaan Kebutuhan Pegawai sesuai dengan Kebutuhan Organisasi | H37: 0.25 | L37: =AVERAGE(L38:L40)*H37 -> 0.25 | M37: =L37/H37 -> 1
A38: 37 | F38: a. | G38: Kebutuhan pegawai yang disusun oleh unit kerja mengacu kepada peta jabatan dan hasil analisis beban kerja untuk masing-masing jabatan | I38: Ya, jika kebutuhan pegawai yang disusun oleh unit kerja mengacu kepada peta jabatan dan hasil analisis beban kerja untuk masing-masing jabatan. | J38: Ya/Tidak | K38: Ya | L38: =IF(J38="Ya/Tidak",IF(K38="Ya",1,IF(K38="Tidak",0,"Blm Diisi")),IF(J38="A/B/C",IF(K38="A",1,IF(K38="B",0.5,IF(K38="C",0,"Blm Diisi"))),IF(J38="A/B/C/D",IF(K38="A",1,IF(K38="B",0.67,IF(K38="C",0.33,IF(K38="D",0,"Blm Diisi")))),IF(J38="A/B/C/D/E",IF(K38="A",1,IF(K38="B",0.75,IF(K38="C",0.5,IF(K38="D",0.25,IF(K38="E",0,"Blm Diisi"))))),IF(J38="%",IF(K38="","Blm Diisi",K38),IF(J38="Jumlah",IF(K38="","Blm Diisi",""),IF(J38="Rupiah",IF(K38="","Blm Diisi",""),IF(J38="","","-")))))))) -> 1 | O38: Unit kerja telah menyusun kebutuhan pegawai yang mengacu kepada peta jabatan dan hasil analisis bebam kerja | P38: 1. Peta Jabatan 2. Analisa Beban Kerja 3. Bezetting 4. Proyeksi Kebutuhan Pegawai | Q38: https://drive.google.com/file/d/1_hJpMIwXoZwV8Y_7tGamuNnVdExy1UUa/view?usp=sharing
A39: 38 | F39: b. | G39: Penempatan pegawai hasil rekrutmen murni mengacu kepada kebutuhan pegawai yang telah disusun per jabatan | I39: a. Jika semua penempatan pegawai hasil rekrutmen murni mengacu kepada kebutuhan pegawai yang telah disusun per jabatan b. Jika sebagian besar penempatan pegawai hasil rekrutmen murni mengacu kepada kebutuhan pegawai yang telah disusun per jabatan c. Jika sebagian kecil penempatan pegawai hasil rekrutmen murni mengacu kepada kebutuhan pegawai yang telah disusun per jabatan d. Jika penempatan pegawai hasil rekrutmen murni tidak mengacu kepada kebutuhan pegawai yang telah disusun per jabatan | J39: A/B/C/D | K39: A | L39: =IF(J39="Ya/Tidak",IF(K39="Ya",1,IF(K39="Tidak",0,"Blm Diisi")),IF(J39="A/B/C",IF(K39="A",1,IF(K39="B",0.5,IF(K39="C",0,"Blm Diisi"))),IF(J39="A/B/C/D",IF(K39="A",1,IF(K39="B",0.67,IF(K39="C",0.33,IF(K39="D",0,"Blm Diisi")))),IF(J39="A/B/C/D/E",IF(K39="A",1,IF(K39="B",0.75,IF(K39="C",0.5,IF(K39="D",0.25,IF(K39="E",0,"Blm Diisi"))))),IF(J39="%",IF(K39="","Blm Diisi",K39),IF(J39="Jumlah",IF(K39="","Blm Diisi",""),IF(J39="Rupiah",IF(K39="","Blm Diisi",""),IF(J39="","","-")))))))) -> 1 | O39: Unit kerja telah menempatan pegawai hasil rekrutmen murni mengacu kepada kebutuhan pegawai yang telah disusun perjabatan | P39: 1.Laporan Penempatan Pegawai, yang memuat: a. Jumlah Kebutuhan Pegawai b. Spesifikasi Kebutuhan Pegawai c. Hasil Penerimaan Pegawai d. Penjelasan Penempatan Pegawai Hasil Rektrutmen e. Analisa kesesuaian penempatan dengan kebutuhan 2. SK Penempatan Pegawai 3. Pengumuman Penerimaan Pegawai Hasil Rekrutmen | Q39: https://drive.google.com/file/d/1QCMJhFh6Sshu6mW-JAJTNfNhkjEs96LW/view?usp=sharing
A40: 39 | F40: c. | G40: Telah dilakukan monitoring dan dan evaluasi terhadap penempatan pegawai rekrutmen untuk memenuhi kebutuhan jabatan dalam organisasi telah memberikan perbaikan terhadap kinerja unit kerja | I40: Ya, jika sudah dilakukan monitoring dan evaluasi terhadap penempatan pegawai hasil rekrutmen untuk memenuhi kebutuhan jabatan dalam organisasi telah memberikan perbaikan terhadap kinerja unit kerja. | J40: Ya/Tidak | K40: Ya | L40: =IF(J40="Ya/Tidak",IF(K40="Ya",1,IF(K40="Tidak",0,"Blm Diisi")),IF(J40="A/B/C",IF(K40="A",1,IF(K40="B",0.5,IF(K40="C",0,"Blm Diisi"))),IF(J40="A/B/C/D",IF(K40="A",1,IF(K40="B",0.67,IF(K40="C",0.33,IF(K40="D",0,"Blm Diisi")))),IF(J40="A/B/C/D/E",IF(K40="A",1,IF(K40="B",0.75,IF(K40="C",0.5,IF(K40="D",0.25,IF(K40="E",0,"Blm Diisi"))))),IF(J40="%",IF(K40="","Blm Diisi",K40),IF(J40="Jumlah",IF(K40="","Blm Diisi",""),IF(J40="Rupiah",IF(K40="","Blm Diisi",""),IF(J40="","","-")))))))) -> 1 | O40: Unit kerja sudah melakukan monitoring dan evaluasi terhadap penempatan pegawai hasil rekrutmen untuk memenuhi kebutuhan jabatan dalam organisasi | P40: 1. Laporan Monev atas Penempatan Pegawai Hasil Rekrutmen 2. Bukti Perbaikan Kinerja atas Rektrutmen Pegawai. | Q40: https://drive.google.com/file/d/1pXcuM0nBvBXDwbemQXCpyWVgyivAS39V/view?usp=sharing
...
